<?xml version='1.0' encoding='UTF-8'?>
<robot name="hand_v3_model">
  <link name="base_link">
    <inertial>
      <origin xyz="-0.0159368448712576 0.000289702026784673 0.0253395763176757" rpy="0.0 -0.0 0.0"/>
      <mass value="0.185756222335551"/>
      <inertia ixx="0.000113540618351959" ixy="-2.50867366425369e-07" ixz="1.61558068388728e-06" iyy="8.83117378270966e-05" iyz="1.59185421854018e-08" izz="0.000173634364629917"/>
    </inertial>
    <visual>
      <geometry>
        <mesh filename="package://hand_v3_model/meshes/base_link.dae"/>
      </geometry>
      <material name=""/>
      <origin xyz="0.0 0.0 0.0" rpy="0.0 -0.0 0.0"/>
    </visual>
    <collision>
      <geometry>
        <mesh filename="package://hand_v3_model/meshes/base_link.dae"/>
      </geometry>
      <origin xyz="0.0 0.0 0.0" rpy="0.0 -0.0 0.0"/>
    </collision>
  </link>
  <link name="arm_link1">
    <inertial>
      <origin xyz="-0.00978848438025783 0.000384177196331765 -0.0621576063561142" rpy="0.0 -0.0 0.0"/>
      <mass value="0.193074721865222"/>
      <inertia ixx="3.80213740266299e-05" ixy="-2.21684269435204e-06" ixz="-1.00323348399987e-08" iyy="4.53666816375235e-05" iyz="-3.12451267361753e-08" izz="5.42874707579927e-05"/>
    </inertial>
    <visual>
      <geometry>
        <mesh filename="package://hand_v3_model/meshes/arm_link1.dae"/>
      </geometry>
      <material name=""/>
      <origin xyz="-1.21797336860599e-14 1.09007835125724e-14 -0.0710000000000039" rpy="0.0 -0.0 0.0"/>
    </visual>
    <collision>
      <geometry>
        <mesh filename="package://hand_v3_model/meshes/arm_link1.dae"/>
      </geometry>
      <origin xyz="-1.21797336860599e-14 1.09007835125724e-14 -0.0710000000000039" rpy="0.0 -0.0 0.0"/>
    </collision>
  </link>
  <link name="arm_link2">
    <inertial>
      <origin xyz="4.83407049837964e-05 5.06154260248703e-05 -0.0995489576359955" rpy="0.0 -0.0 0.0"/>
      <mass value="0.0413445310117904"/>
      <inertia ixx="6.13742631381391e-06" ixy="-1.14668747691786e-08" ixz="-3.13675118837437e-09" iyy="5.39269102743716e-06" iyz="-1.89827016745712e-08" izz="3.76704222934287e-06"/>
    </inertial>
    <visual>
      <geometry>
        <mesh filename="package://hand_v3_model/meshes/arm_link2.dae"/>
      </geometry>
      <material name=""/>
      <origin xyz="-1.23408346606709e-14 2.13996621527825e-14 -0.141700000000004" rpy="0.0 -0.0 0.0"/>
    </visual>
    <collision>
      <geometry>
        <mesh filename="package://hand_v3_model/meshes/arm_link2.dae"/>
      </geometry>
      <origin xyz="-1.23408346606709e-14 2.13996621527825e-14 -0.141700000000004" rpy="0.0 -0.0 0.0"/>
    </collision>
  </link>
  <link name="arm_link3">
    <inertial>
      <origin xyz="-7.32385338863604e-05 0.000168976972247172 -0.177623391706597" rpy="0.0 -0.0 0.0"/>
      <mass value="0.0285401131313353"/>
      <inertia ixx="3.28801768228182e-06" ixy="1.14697545620646e-08" ixz="1.89840699729582e-08" iyy="3.41808882123853e-06" iyz="-6.70904151464841e-09" izz="2.74702490399628e-06"/>
    </inertial>
    <visual>
      <geometry>
        <mesh filename="package://hand_v3_model/meshes/arm_link3.dae"/>
      </geometry>
      <material name=""/>
      <origin xyz="-1.36338070770796e-14 2.10989116680624e-14 -0.210700000000004" rpy="0.0 -0.0 0.0"/>
    </visual>
    <collision>
      <geometry>
        <mesh filename="package://hand_v3_model/meshes/arm_link3.dae"/>
      </geometry>
      <origin xyz="-1.36338070770796e-14 2.10989116680624e-14 -0.210700000000004" rpy="0.0 -0.0 0.0"/>
    </collision>
  </link>
  <link name="hand_link">
    <inertial>
      <origin xyz="0.00239249532730597 -0.000454670310455432 -0.198061785013894" rpy="0.0 -0.0 0.0"/>
      <mass value="0.0862355112971162"/>
      <inertia ixx="1.21593177078041e-05" ixy="-6.20382094262845e-08" ixz="-3.92636544873787e-08" iyy="5.80978848403572e-06" iyz="3.49334419785276e-07" izz="1.15352340969383e-05"/>
    </inertial>
    <visual>
      <geometry>
        <mesh filename="package://hand_v3_model/meshes/hand_link.dae"/>
      </geometry>
      <material name=""/>
      <origin xyz="-1.07485432813368e-14 2.1597072595029e-14 -0.257700000000001" rpy="0.0 -0.0 0.0"/>
    </visual>
    <collision>
      <geometry>
        <mesh filename="package://hand_v3_model/meshes/hand_link.dae"/>
      </geometry>
      <origin xyz="-1.07485432813368e-14 2.1597072595029e-14 -0.257700000000001" rpy="0.0 -0.0 0.0"/>
    </collision>
  </link>
  <link name="thumb_pulley_link">
    <inertial>
      <origin xyz="0.00499396665093409 -0.0288234692035366 0.300540813255855" rpy="0.0 -0.0 0.0"/>
      <mass value="0.000573068394145989"/>
      <inertia ixx="1.01383604562528e-08" ixy="2.14620718289238e-10" ixz="6.10690723533873e-12" iyy="1.04389572865727e-08" iyz="-1.17292338601506e-11" izz="1.95368356803049e-08"/>
    </inertial>
    <visual>
      <geometry>
        <mesh filename="package://hand_v3_model/meshes/thumb_pulley_link.dae"/>
      </geometry>
      <material name=""/>
      <origin xyz="0.00510473038958318 -0.0290362596907637 0.299200005856291" rpy="3.14159265358979 -0.0 3.14159265358979"/>
    </visual>
    <collision>
      <geometry>
        <mesh filename="package://hand_v3_model/meshes/thumb_pulley_link.dae"/>
      </geometry>
      <origin xyz="0.00510473038958318 -0.0290362596907637 0.299200005856291" rpy="3.14159265358979 -0.0 3.14159265358979"/>
    </collision>
  </link>
  <link name="index_pulley_link">
    <inertial>
      <origin xyz="0.0104400800960098 0.0260043933773204 0.338052915986819" rpy="0.0 -0.0 0.0"/>
      <mass value="0.00101512886583035"/>
      <inertia ixx="5.80350843229943e-08" ixy="1.70386993085394e-11" ixz="3.48093654518268e-12" iyy="3.04025634559552e-08" iyz="-2.09219414876704e-10" izz="2.94212062442424e-08"/>
    </inertial>
    <visual>
      <geometry>
        <mesh filename="package://hand_v3_model/meshes/index_pulley_link.dae"/>
      </geometry>
      <material name=""/>
      <origin xyz="0.00909526961041773 0.0262348940717034 0.338100006335385" rpy="3.14159265358979 1.30921128989166e-15 0.0"/>
    </visual>
    <collision>
      <geometry>
        <mesh filename="package://hand_v3_model/meshes/index_pulley_link.dae"/>
      </geometry>
      <origin xyz="0.00909526961041773 0.0262348940717034 0.338100006335385" rpy="3.14159265358979 1.30921128989166e-15 0.0"/>
    </collision>
  </link>
  <link name="middle_pulley_link">
    <inertial>
      <origin xyz="0.00750536511192664 0.0104854577895602 0.346062202823937" rpy="0.0 -0.0 0.0"/>
      <mass value="0.00126450613447782"/>
      <inertia ixx="6.15321269949602e-08" ixy="1.7270734870826e-10" ixz="3.52834045616528e-11" iyy="3.46243381639731e-08" iyz="-2.07046407283457e-10" izz="3.36531735850713e-08"/>
    </inertial>
    <visual>
      <geometry>
        <mesh filename="package://hand_v3_model/meshes/middle_pulley_link.dae"/>
      </geometry>
      <material name=""/>
      <origin xyz="0.00909526961041802 0.0106705007103382 0.346100006335385" rpy="3.14159265358979 1.91588950893966e-15 0.0"/>
    </visual>
    <collision>
      <geometry>
        <mesh filename="package://hand_v3_model/meshes/middle_pulley_link.dae"/>
      </geometry>
      <origin xyz="0.00909526961041802 0.0106705007103382 0.346100006335385" rpy="3.14159265358979 1.91588950893966e-15 0.0"/>
    </collision>
  </link>
  <link name="ring_pulley_link">
    <inertial>
      <origin xyz="0.0104400800960335 -0.00633049887020139 0.341052909651437" rpy="0.0 -0.0 0.0"/>
      <mass value="0.00101512886583036"/>
      <inertia ixx="5.80350843229944e-08" ixy="1.7038699308586e-11" ixz="3.48093654518006e-12" iyy="3.04025634559552e-08" iyz="-2.09219414876704e-10" izz="2.94212062442424e-08"/>
    </inertial>
    <visual>
      <geometry>
        <mesh filename="package://hand_v3_model/meshes/ring_pulley_link.dae"/>
      </geometry>
      <material name=""/>
      <origin xyz="0.00909526961041822 -0.00609999817581914 0.341100000000002" rpy="3.14159265358979 2.58574932440018e-15 0.0"/>
    </visual>
    <collision>
      <geometry>
        <mesh filename="package://hand_v3_model/meshes/ring_pulley_link.dae"/>
      </geometry>
      <origin xyz="0.00909526961041822 -0.00609999817581914 0.341100000000002" rpy="3.14159265358979 2.58574932440018e-15 0.0"/>
    </collision>
  </link>
  <link name="little_pulley_link">
    <inertial>
      <origin xyz="0.0075053651119492 -0.0218312316345219 0.333011508657783" rpy="0.0 -0.0 0.0"/>
      <mass value="0.00126450613447782"/>
      <inertia ixx="6.15321269949601e-08" ixy="1.55728201033398e-10" ixz="8.25922171814842e-11" iyy="3.44348629344565e-08" iyz="-4.37011422796308e-10" izz="3.3842648814588e-08"/>
    </inertial>
    <visual>
      <geometry>
        <mesh filename="package://hand_v3_model/meshes/little_pulley_link.dae"/>
      </geometry>
      <material name=""/>
      <origin xyz="0.00909526961041816 -0.0216643805920936 0.333100000000003" rpy="3.14159265358979 2.66453525910038e-15 0.0"/>
    </visual>
    <collision>
      <geometry>
        <mesh filename="package://hand_v3_model/meshes/little_pulley_link.dae"/>
      </geometry>
      <origin xyz="0.00909526961041816 -0.0216643805920936 0.333100000000003" rpy="3.14159265358979 2.66453525910038e-15 0.0"/>
    </collision>
  </link>
  <link name="adduction_pulley_link">
    <inertial>
      <origin xyz="-0.000393846214060233 -0.00427523428694994 -0.297632293965204" rpy="0.0 -0.0 0.0"/>
      <mass value="0.001757686295804"/>
      <inertia ixx="3.85008956769593e-08" ixy="1.17217652597688e-11" ixz="-6.36420221979036e-10" iyy="7.13845589903268e-08" iyz="5.36365951738641e-12" izz="3.74012740005429e-08"/>
    </inertial>
    <visual>
      <geometry>
        <mesh filename="package://hand_v3_model/meshes/adduction_pulley_link.dae"/>
      </geometry>
      <material name=""/>
      <origin xyz="-0.000104730389583172 -0.00328525673980379 -0.297500000000002" rpy="0.0 -0.0 0.0"/>
    </visual>
    <collision>
      <geometry>
        <mesh filename="package://hand_v3_model/meshes/adduction_pulley_link.dae"/>
      </geometry>
      <origin xyz="-0.000104730389583172 -0.00328525673980379 -0.297500000000002" rpy="0.0 -0.0 0.0"/>
    </collision>
  </link>
  <link name="thumb_link0">
    <inertial>
      <origin xyz="-0.0131984273671712 -0.00725706379200231 -0.291061834200039" rpy="0.0 -0.0 0.0"/>
      <mass value="0.00222751592226221"/>
      <inertia ixx="2.3888924629314e-07" ixy="1.99935318163553e-09" ixz="-6.52098353684233e-10" iyy="9.11947268793252e-08" iyz="6.66199427254774e-08" izz="1.73153324814096e-07"/>
    </inertial>
    <visual>
      <geometry>
        <mesh filename="package://hand_v3_model/meshes/thumb_link0.dae"/>
      </geometry>
      <material name=""/>
      <origin xyz="-0.0131047303895831 -0.0212852595376459 -0.301300003304203" rpy="0.0 -0.0 0.0"/>
    </visual>
    <collision>
      <geometry>
        <mesh filename="package://hand_v3_model/meshes/thumb_link0.dae"/>
      </geometry>
      <origin xyz="-0.0131047303895831 -0.0212852595376459 -0.301300003304203" rpy="0.0 -0.0 0.0"/>
    </collision>
  </link>
  <link name="thumb_link1">
    <inertial>
      <origin xyz="-0.296479123494841 0.0965415981316485 0.098643793725724" rpy="0.0 -0.0 0.0"/>
      <mass value="0.00165203073265575"/>
      <inertia ixx="1.28625246386984e-07" ixy="-4.60513608382968e-09" ixz="-1.29650086921569e-08" iyy="9.85847874936955e-08" iyz="4.44238701248018e-08" izz="5.69370799493245e-08"/>
    </inertial>
    <visual>
      <geometry>
        <mesh filename="package://hand_v3_model/meshes/thumb_link1.dae"/>
      </geometry>
      <material name=""/>
      <origin xyz="-0.295602266948084 0.0904879645075565 0.110163941716504" rpy="2.34172725852824 1.03834412827171 1.81671012667268"/>
    </visual>
    <collision>
      <geometry>
        <mesh filename="package://hand_v3_model/meshes/thumb_link1.dae"/>
      </geometry>
      <origin xyz="-0.295602266948084 0.0904879645075565 0.110163941716504" rpy="2.34172725852824 1.03834412827171 1.81671012667268"/>
    </collision>
  </link>
  <link name="thumb_link2">
    <inertial>
      <origin xyz="-0.323396126487467 0.0939104839174868 0.102638221515411" rpy="0.0 -0.0 0.0"/>
      <mass value="0.00106407341908137"/>
      <inertia ixx="5.01077093105504e-08" ixy="-2.93123438162397e-09" ixz="-7.12065285952429e-09" iyy="3.84021169917255e-08" iyz="1.6054620341175e-08" izz="2.71055509753875e-08"/>
    </inertial>
    <visual>
      <geometry>
        <mesh filename="package://hand_v3_model/meshes/thumb_link2.dae"/>
      </geometry>
      <material name=""/>
      <origin xyz="-0.323602266948084 0.0904879645075558 0.110163941716505" rpy="2.34172725852824 1.03834412827171 1.81671012667268"/>
    </visual>
    <collision>
      <geometry>
        <mesh filename="package://hand_v3_model/meshes/thumb_link2.dae"/>
      </geometry>
      <origin xyz="-0.323602266948084 0.0904879645075558 0.110163941716505" rpy="2.34172725852824 1.03834412827171 1.81671012667268"/>
    </collision>
  </link>
  <link name="index_link0">
    <inertial>
      <origin xyz="-0.358246589723696 -0.0296537586327549 0.00456477436993843" rpy="0.0 -0.0 0.0"/>
      <mass value="0.000862118530230645"/>
      <inertia ixx="2.74838732877092e-08" ixy="4.60249360851945e-11" ixz="1.64629832322558e-09" iyy="2.4815764455565e-08" iyz="-2.9337068423474e-10" izz="1.83260236280527e-08"/>
    </inertial>
    <visual>
      <geometry>
        <mesh filename="package://hand_v3_model/meshes/index_link0.dae"/>
      </geometry>
      <material name=""/>
      <origin xyz="-0.358299998213794 -0.0292852465286189 0.00900476462980921" rpy="-3.14159264884631 1.5707962257303 -3.14159264884631"/>
    </visual>
    <collision>
      <geometry>
        <mesh filename="package://hand_v3_model/meshes/index_link0.dae"/>
      </geometry>
      <origin xyz="-0.358299998213794 -0.0292852465286189 0.00900476462980921" rpy="-3.14159264884631 1.5707962257303 -3.14159264884631"/>
    </collision>
  </link>
  <link name="index_link1">
    <inertial>
      <origin xyz="-0.368496020562021 -0.0291853153023425 -0.00250964222369502" rpy="0.0 -0.0 0.0"/>
      <mass value="0.00165203434128294"/>
      <inertia ixx="1.32129915581458e-07" ixy="-6.62321335808929e-13" ixz="-8.88666584045425e-10" iyy="1.25083225521205e-07" iyz="-1.81097402604625e-12" izz="2.69357717030325e-08"/>
    </inertial>
    <visual>
      <geometry>
        <mesh filename="package://hand_v3_model/meshes/index_link1.dae"/>
      </geometry>
      <material name=""/>
      <origin xyz="-0.369364999480807 -0.0291852457947127 0.0105047646298093" rpy="-3.14159264406214 1.5707962257303 -3.14159264406214"/>
    </visual>
    <collision>
      <geometry>
        <mesh filename="package://hand_v3_model/meshes/index_link1.dae"/>
      </geometry>
      <origin xyz="-0.369364999480807 -0.0291852457947127 0.0105047646298093" rpy="-3.14159264406214 1.5707962257303 -3.14159264406214"/>
    </collision>
  </link>
  <link name="index_link2">
    <inertial>
      <origin xyz="-0.396507626849074 -0.0291853490981649 -1.4064543966073e-05" rpy="0.0 -0.0 0.0"/>
      <mass value="0.00138867181880575"/>
      <inertia ixx="8.3179130954676e-08" ixy="-7.83803287508677e-13" ixz="-8.1545223384782e-10" iyy="7.7708847768507e-08" iyz="-1.730770425077e-12" izz="2.23707352283301e-08"/>
    </inertial>
    <visual>
      <geometry>
        <mesh filename="package://hand_v3_model/meshes/index_link2.dae"/>
      </geometry>
      <material name=""/>
      <origin xyz="-0.397364999480808 -0.0291852457947131 0.0105047646298092" rpy="-3.1415926456317 1.5707962257303 -3.1415926456317"/>
    </visual>
    <collision>
      <geometry>
        <mesh filename="package://hand_v3_model/meshes/index_link2.dae"/>
      </geometry>
      <origin xyz="-0.397364999480808 -0.0291852457947131 0.0105047646298092" rpy="-3.1415926456317 1.5707962257303 -3.1415926456317"/>
    </collision>
  </link>
  <link name="index_link3">
    <inertial>
      <origin xyz="-0.418924246785047 -0.0291851992926505 0.00235918931256635" rpy="0.0 -0.0 0.0"/>
      <mass value="0.0010642513972353"/>
      <inertia ixx="5.23369094826426e-08" ixy="-3.35288480460072e-13" ixz="-3.64395617545436e-09" iyy="4.88130690506473e-08" iyz="5.94614647011101e-13" izz="1.45125530907261e-08"/>
    </inertial>
    <visual>
      <geometry>
        <mesh filename="package://hand_v3_model/meshes/index_link3.dae"/>
      </geometry>
      <material name=""/>
      <origin xyz="-0.420364999480808 -0.0291852457947134 0.0105047646298092" rpy="-3.1415926460144 1.5707962257303 -3.1415926460144"/>
    </visual>
    <collision>
      <geometry>
        <mesh filename="package://hand_v3_model/meshes/index_link3.dae"/>
      </geometry>
      <origin xyz="-0.420364999480808 -0.0291852457947134 0.0105047646298092" rpy="-3.1415926460144 1.5707962257303 -3.1415926460144"/>
    </collision>
  </link>
  <link name="middle_link0">
    <inertial>
      <origin xyz="-0.364246615288256 -0.0114537386699524 0.00457789737568003" rpy="0.0 -0.0 0.0"/>
      <mass value="0.000862150655926043"/>
      <inertia ixx="2.74370185779519e-08" ixy="4.61263021077474e-11" ixz="1.63570678602322e-09" iyy="2.47678482511169e-08" iyz="-3.62922479724337e-10" izz="1.83271437549206e-08"/>
    </inertial>
    <visual>
      <geometry>
        <mesh filename="package://hand_v3_model/meshes/middle_link0.dae"/>
      </geometry>
      <material name=""/>
      <origin xyz="-0.364300000549786 -0.0111852451755166 0.00900476462980938" rpy="3.14159265128834 1.5707962257303 3.14159265128833"/>
    </visual>
    <collision>
      <geometry>
        <mesh filename="package://hand_v3_model/meshes/middle_link0.dae"/>
      </geometry>
      <origin xyz="-0.364300000549786 -0.0111852451755166 0.00900476462980938" rpy="3.14159265128834 1.5707962257303 3.14159265128833"/>
    </collision>
  </link>
  <link name="middle_link1">
    <inertial>
      <origin xyz="-0.374466227181728 -0.0111852850134854 -0.00545182219025148" rpy="0.0 -0.0 0.0"/>
      <mass value="0.00195707994885378"/>
      <inertia ixx="2.13983170855394e-07" ixy="-4.80398266291894e-13" ixz="-1.32901123014075e-09" iyy="2.04977420227209e-07" iyz="-1.72954876503655e-12" izz="3.21864462364343e-08"/>
    </inertial>
    <visual>
      <geometry>
        <mesh filename="package://hand_v3_model/meshes/middle_link1.dae"/>
      </geometry>
      <material name=""/>
      <origin xyz="-0.37536499948081 -0.0111852457947112 0.0105047646298094" rpy="3.14159265236924 1.5707962257303 3.14159265236923"/>
    </visual>
    <collision>
      <geometry>
        <mesh filename="package://hand_v3_model/meshes/middle_link1.dae"/>
      </geometry>
      <origin xyz="-0.37536499948081 -0.0111852457947112 0.0105047646298094" rpy="3.14159265236924 1.5707962257303 3.14159265236923"/>
    </collision>
  </link>
  <link name="middle_link2">
    <inertial>
      <origin xyz="-0.408507626849092 -0.0111853490981735 -1.40645439640121e-05" rpy="0.0 -0.0 0.0"/>
      <mass value="0.00138867181880573"/>
      <inertia ixx="8.31791309546753e-08" ixy="-7.83803287530291e-13" ixz="-8.15452233848222e-10" iyy="7.77088477685063e-08" iyz="-1.73077042527186e-12" izz="2.23707352283299e-08"/>
    </inertial>
    <visual>
      <geometry>
        <mesh filename="package://hand_v3_model/meshes/middle_link2.dae"/>
      </geometry>
      <material name=""/>
      <origin xyz="-0.40936499948081 -0.0111852457947114 0.0105047646298094" rpy="-3.1415926517105 1.5707962257303 -3.1415926517105"/>
    </visual>
    <collision>
      <geometry>
        <mesh filename="package://hand_v3_model/meshes/middle_link2.dae"/>
      </geometry>
      <origin xyz="-0.40936499948081 -0.0111852457947114 0.0105047646298094" rpy="-3.1415926517105 1.5707962257303 -3.1415926517105"/>
    </collision>
  </link>
  <link name="middle_link3">
    <inertial>
      <origin xyz="-0.430924246785064 -0.0111851992926589 0.00235918931256839" rpy="0.0 -0.0 0.0"/>
      <mass value="0.00106425139723533"/>
      <inertia ixx="5.23369094826472e-08" ixy="-3.35288480500077e-13" ixz="-3.64395617545474e-09" iyy="4.88130690506518e-08" iyz="5.94614647117015e-13" izz="1.45125530907262e-08"/>
    </inertial>
    <visual>
      <geometry>
        <mesh filename="package://hand_v3_model/meshes/middle_link3.dae"/>
      </geometry>
      <material name=""/>
      <origin xyz="-0.43236499948081 -0.0111852457947114 0.0105047646298096" rpy="3.14159265324505 1.57079622355662 3.14159265324505"/>
    </visual>
    <collision>
      <geometry>
        <mesh filename="package://hand_v3_model/meshes/middle_link3.dae"/>
      </geometry>
      <origin xyz="-0.43236499948081 -0.0111852457947114 0.0105047646298096" rpy="3.14159265324505 1.57079622355662 3.14159265324505"/>
    </collision>
  </link>
  <link name="ring_link0">
    <inertial>
      <origin xyz="-0.359246592312053 0.00718323715862302 0.00457779055610991" rpy="0.0 -0.0 0.0"/>
      <mass value="0.000862141381321495"/>
      <inertia ixx="2.74365725109563e-08" ixy="-4.6104654949058e-11" ixz="1.63564836675834e-09" iyy="2.47668560611884e-08" iyz="3.63501748154234e-10" izz="1.83274320135936e-08"/>
    </inertial>
    <visual>
      <geometry>
        <mesh filename="package://hand_v3_model/meshes/ring_link0.dae"/>
      </geometry>
      <material name=""/>
      <origin xyz="-0.359299998213794 0.00681475347138234 0.00900476462980948" rpy="3.14159265006496 1.5707962257303 3.14159265006495"/>
    </visual>
    <collision>
      <geometry>
        <mesh filename="package://hand_v3_model/meshes/ring_link0.dae"/>
      </geometry>
      <origin xyz="-0.359299998213794 0.00681475347138234 0.00900476462980948" rpy="3.14159265006496 1.5707962257303 3.14159265006495"/>
    </collision>
  </link>
  <link name="ring_link1">
    <inertial>
      <origin xyz="-0.369466227181739 0.00671471498651375 -0.00545182219025299" rpy="0.0 -0.0 0.0"/>
      <mass value="0.00195707994885374"/>
      <inertia ixx="2.13983170855384e-07" ixy="-4.80398266690734e-13" ixz="-1.32901123014309e-09" iyy="2.04977420227199e-07" iyz="-1.72954876670285e-12" izz="3.21864462364331e-08"/>
    </inertial>
    <visual>
      <geometry>
        <mesh filename="package://hand_v3_model/meshes/ring_link1.dae"/>
      </geometry>
      <material name=""/>
      <origin xyz="-0.370364999480808 0.00671475420528815 0.0105047646298096" rpy="3.14159263674689 1.5707962257303 3.14159263674689"/>
    </visual>
    <collision>
      <geometry>
        <mesh filename="package://hand_v3_model/meshes/ring_link1.dae"/>
      </geometry>
      <origin xyz="-0.370364999480808 0.00671475420528815 0.0105047646298096" rpy="3.14159263674689 1.5707962257303 3.14159263674689"/>
    </collision>
  </link>
  <link name="ring_link2">
    <inertial>
      <origin xyz="-0.403507626848989 0.0067146509018258 -1.40645438526099e-05" rpy="0.0 -0.0 0.0"/>
      <mass value="0.00138867181880573"/>
      <inertia ixx="8.31791309546734e-08" ixy="-7.83803287628791e-13" ixz="-8.15452233848557e-10" iyy="7.77088477685041e-08" iyz="-1.73077042516637e-12" izz="2.23707352283295e-08"/>
    </inertial>
    <visual>
      <geometry>
        <mesh filename="package://hand_v3_model/meshes/ring_link2.dae"/>
      </geometry>
      <material name=""/>
      <origin xyz="-0.404364999480808 0.00671475420528798 0.0105047646299231" rpy="3.14159264995864 1.5707962257303 3.14159264995864"/>
    </visual>
    <collision>
      <geometry>
        <mesh filename="package://hand_v3_model/meshes/ring_link2.dae"/>
      </geometry>
      <origin xyz="-0.404364999480808 0.00671475420528798 0.0105047646299231" rpy="3.14159264995864 1.5707962257303 3.14159264995864"/>
    </collision>
  </link>
  <link name="ring_link3">
    <inertial>
      <origin xyz="-0.42592465717889 0.00671473460798005 0.00236116864609563" rpy="0.0 -0.0 0.0"/>
      <mass value="0.00106407623116358"/>
      <inertia ixx="5.23142399203294e-08" ixy="-1.51110018988025e-13" ixz="-3.63902192429204e-09" iyy="4.8789779132009e-08" iyz="-2.53656412409941e-13" izz="1.45110052052983e-08"/>
    </inertial>
    <visual>
      <geometry>
        <mesh filename="package://hand_v3_model/meshes/ring_link3.dae"/>
      </geometry>
      <material name=""/>
      <origin xyz="-0.427364999480808 0.00671475420528813 0.0105047646299231" rpy="3.14159264969729 1.5707962257303 3.14159264969729"/>
    </visual>
    <collision>
      <geometry>
        <mesh filename="package://hand_v3_model/meshes/ring_link3.dae"/>
      </geometry>
      <origin xyz="-0.427364999480808 0.00671475420528813 0.0105047646299231" rpy="3.14159264969729 1.5707962257303 3.14159264969729"/>
    </collision>
  </link>
  <link name="little_link0">
    <inertial>
      <origin xyz="-0.354246569885181 0.0251833629073577 0.00456488752201531" rpy="0.0 -0.0 0.0"/>
      <mass value="0.000862121012813642"/>
      <inertia ixx="2.74833063697148e-08" ixy="-4.6001529297172e-11" ixz="1.64625439575554e-09" iyy="2.48141488184599e-08" iyz="2.92884480539031e-10" izz="1.83268341935774e-08"/>
    </inertial>
    <visual>
      <geometry>
        <mesh filename="package://hand_v3_model/meshes/little_link0.dae"/>
      </geometry>
      <material name=""/>
      <origin xyz="-0.354299998213794 0.0248147534713826 0.00900476462980943" rpy="3.14159265006496 1.5707962257303 3.14159265006495"/>
    </visual>
    <collision>
      <geometry>
        <mesh filename="package://hand_v3_model/meshes/little_link0.dae"/>
      </geometry>
      <origin xyz="-0.354299998213794 0.0248147534713826 0.00900476462980943" rpy="3.14159265006496 1.5707962257303 3.14159265006495"/>
    </collision>
  </link>
  <link name="little_link1">
    <inertial>
      <origin xyz="-0.364507626849103 0.0247146509018844 -1.40645439668172e-05" rpy="0.0 -0.0 0.0"/>
      <mass value="0.00138867181880572"/>
      <inertia ixx="8.31791309546738e-08" ixy="-7.83803287616177e-13" ixz="-8.15452233848282e-10" iyy="7.77088477685046e-08" iyz="-1.73077042514485e-12" izz="2.23707352283295e-08"/>
    </inertial>
    <visual>
      <geometry>
        <mesh filename="package://hand_v3_model/meshes/little_link1.dae"/>
      </geometry>
      <material name=""/>
      <origin xyz="-0.365364999480807 0.0247147542052884 0.0105047646298095" rpy="3.14159265034958 1.5707962257303 3.14159265034958"/>
    </visual>
    <collision>
      <geometry>
        <mesh filename="package://hand_v3_model/meshes/little_link1.dae"/>
      </geometry>
      <origin xyz="-0.365364999480807 0.0247147542052884 0.0105047646298095" rpy="3.14159265034958 1.5707962257303 3.14159265034958"/>
    </collision>
  </link>
  <link name="little_link2">
    <inertial>
      <origin xyz="-0.387507626849111 0.0247146509018449 -1.4064543966439e-05" rpy="0.0 -0.0 0.0"/>
      <mass value="0.0013886718188057"/>
      <inertia ixx="8.31791309546721e-08" ixy="-7.83803287853618e-13" ixz="-8.15452233849782e-10" iyy="7.77088477685027e-08" iyz="-1.73077042580625e-12" izz="2.2370735228329e-08"/>
    </inertial>
    <visual>
      <geometry>
        <mesh filename="package://hand_v3_model/meshes/little_link2.dae"/>
      </geometry>
      <material name=""/>
      <origin xyz="-0.388364999480807 0.0247147542052882 0.0105047646298094" rpy="3.14159265019532 1.57079622355662 3.14159265019532"/>
    </visual>
    <collision>
      <geometry>
        <mesh filename="package://hand_v3_model/meshes/little_link2.dae"/>
      </geometry>
      <origin xyz="-0.388364999480807 0.0247147542052882 0.0105047646298094" rpy="3.14159265019532 1.57079622355662 3.14159265019532"/>
    </collision>
  </link>
  <link name="little_link3">
    <inertial>
      <origin xyz="-0.409924657179012 0.0247147346079994 0.00236116864598134" rpy="0.0 -0.0 0.0"/>
      <mass value="0.00106407623116358"/>
      <inertia ixx="5.23142399203297e-08" ixy="-1.51110019092363e-13" ixz="-3.63902192429213e-09" iyy="4.87897791320094e-08" iyz="-2.53656411614198e-13" izz="1.45110052052982e-08"/>
    </inertial>
    <visual>
      <geometry>
        <mesh filename="package://hand_v3_model/meshes/little_link3.dae"/>
      </geometry>
      <material name=""/>
      <origin xyz="-0.411364999480807 0.0247147542052885 0.0105047646298093" rpy="3.14159264770445 1.5707962257303 3.14159264770445"/>
    </visual>
    <collision>
      <geometry>
        <mesh filename="package://hand_v3_model/meshes/little_link3.dae"/>
      </geometry>
      <origin xyz="-0.411364999480807 0.0247147542052885 0.0105047646298093" rpy="3.14159264770445 1.5707962257303 3.14159264770445"/>
    </collision>
  </link>
  <joint name="arm_joint0" type="revolute">
    <limit effort="0.0" velocity="4.553" lower="-2.06167" upper="0.41233"/>
    <parent link="base_link"/>
    <child link="arm_link1"/>
    <axis xyz=" 0. -1.  0."/>
    <origin xyz="0.0 0.0 0.0710000000000039" rpy="0.0 -0.0 0.0"/>
  </joint>
  <joint name="arm_joint1" type="revolute">
    <limit effort="0.0" velocity="6.545" lower="-2.3562" upper="2.3562"/>
    <parent link="arm_link1"/>
    <child link="arm_link2"/>
    <axis xyz="0. 0. 1."/>
    <origin xyz="0.0 0.0 0.0707" rpy="0.0 -0.0 0.0"/>
  </joint>
  <joint name="arm_joint2" type="revolute">
    <limit effort="0.0" velocity="6.545" lower="-1.5708" upper="0.06"/>
    <parent link="arm_link2"/>
    <child link="arm_link3"/>
    <axis xyz=" 0. -1.  0."/>
    <origin xyz="0.0 0.0 0.069" rpy="0.0 -0.0 0.0"/>
  </joint>
  <joint name="hand_base_joint" type="revolute">
    <limit effort="0.0" velocity="6.545" lower="-1.5708" upper="1.5708"/>
    <parent link="arm_link3"/>
    <child link="hand_link"/>
    <axis xyz="-1.  0.  0."/>
    <origin xyz="0.0 0.0 0.046999999999997" rpy="0.0 -0.0 0.0"/>
  </joint>
  <joint name="thumb_pulley_joint" type="continuous">
    <limit effort="0.0" velocity="10.0"/>
    <parent link="hand_link"/>
    <child link="thumb_pulley_link"/>
    <axis xyz="0. 0. 1."/>
    <origin xyz="0.00510473038957243 0.0290362596907853 0.0415000058562903" rpy="3.14159265358979 -0.0 3.14159265358979"/>
  </joint>
  <joint name="index_pulley_joint" type="continuous">
    <limit effort="0.0" velocity="10.0"/>
    <parent link="hand_link"/>
    <child link="index_pulley_link"/>
    <axis xyz="1. 0. 0."/>
    <origin xyz="-0.00909526961042804 0.026234894071725 0.080400006335384" rpy="3.14159265358979 -0.0 0.0"/>
  </joint>
  <joint name="middle_pulley_joint" type="continuous">
    <limit effort="0.0" velocity="10.0"/>
    <parent link="hand_link"/>
    <child link="middle_pulley_link"/>
    <axis xyz="-1.  0.  0."/>
    <origin xyz="-0.0090952696104281 0.0106705007103598 0.088400006335384" rpy="3.14159265358979 -0.0 0.0"/>
  </joint>
  <joint name="ring_pulley_joint" type="continuous">
    <limit effort="0.0" velocity="10.0"/>
    <parent link="hand_link"/>
    <child link="ring_pulley_link"/>
    <axis xyz="-1.  0.  0."/>
    <origin xyz="-0.00909526961042809 -0.00609999817579755 0.0834000000000015" rpy="3.14159265358979 -0.0 0.0"/>
  </joint>
  <joint name="little_pulley_joint" type="continuous">
    <limit effort="0.0" velocity="10.0"/>
    <parent link="hand_link"/>
    <child link="little_pulley_link"/>
    <axis xyz="-1.  0.  0."/>
    <origin xyz="-0.00909526961042802 -0.021664380592072 0.0754000000000016" rpy="3.14159265358979 -0.0 0.0"/>
  </joint>
  <joint name="adduction_pulley_joint" type="continuous">
    <limit effort="0.0" velocity="6.545"/>
    <parent link="hand_link"/>
    <child link="adduction_pulley_link"/>
    <axis xyz="0. 1. 0."/>
    <origin xyz="0.000104730389572423 0.00328525673982538 0.0398000000000016" rpy="0.0 -0.0 0.0"/>
  </joint>
  <joint name="thumb_joint0" type="revolute">
    <limit effort="0.0" velocity="10.0" lower="-1.0471975511965976" upper="0.0"/>
    <parent link="hand_link"/>
    <child link="thumb_link0"/>
    <axis xyz=" 0.  0. -1."/>
    <origin xyz="0.0131047303895724 0.0212852595376675 0.0436000033042019" rpy="0.0 -0.0 0.0"/>
  </joint>
  <joint name="thumb_joint1" type="revolute">
    <limit effort="0.0" velocity="10.0" lower="0.0" upper="1.5708"/>
    <parent link="thumb_link0"/>
    <child link="thumb_link1"/>
    <axis xyz=" 0. 1.  0."/>
    <origin xyz="0.00072316968380136 0.0243257662747911 0.0234049235201093" rpy="-2.28547286926153 -1.0006691861817 1.80181397893486"/>
  </joint>
  <joint name="thumb_joint2" type="revolute">
    <limit effort="0.0" velocity="10.0" lower="0.0" upper="1.5708"/>
    <parent link="thumb_link1"/>
    <child link="thumb_link2"/>
    <axis xyz=" 0. 1.  0."/>
    <origin xyz="0.0279999999999995 0.0 0.0" rpy="0.0 -0.0 0.0"/>
  </joint>
  <joint name="index_joint0" type="revolute">
    <limit effort="0.0" velocity="6.545" lower="0.0" upper="1.2217"/>
    <parent link="hand_link"/>
    <child link="index_link0"/>
    <axis xyz=" 0.  0. 1."/>
    <origin xyz="0.00900472854133688 0.0292852465286407 0.100599999120763" rpy="-3.14159264732828 -1.5707962257303 3.14159264732828"/>
  </joint>
  <joint name="index_joint1" type="revolute">
    <limit effort="0.0" velocity="10.0" lower="0.0" upper="1.5708"/>
    <parent link="index_link0"/>
    <child link="index_link1"/>
    <axis xyz=" 0. 1.  0."/>
    <origin xyz="0.0110650012670139 -0.000100000733906178 -0.00150000000000009" rpy="0.0 -0.0 0.0"/>
  </joint>
  <joint name="index_joint2" type="revolute">
    <limit effort="0.0" velocity="10.0" lower="0.0" upper="1.5708"/>
    <parent link="index_link1"/>
    <child link="index_link2"/>
    <axis xyz=" 0. 1.  0."/>
    <origin xyz="0.028 0.0 0.0" rpy="0.0 -0.0 0.0"/>
  </joint>
  <joint name="index_joint3" type="revolute">
    <limit effort="0.0" velocity="10.0" lower="0.0" upper="1.5708"/>
    <parent link="index_link2"/>
    <child link="index_link3"/>
    <axis xyz=" 0. 1.  0."/>
    <origin xyz="0.023 0.0 0.0" rpy="0.0 -0.0 0.0"/>
  </joint>
  <joint name="middle_joint0" type="revolute">
    <limit effort="0.0" velocity="6.545" lower="0.0" upper="1.2217"/>
    <parent link="hand_link"/>
    <child link="middle_link0"/>
    <axis xyz="0. 0. 1."/>
    <origin xyz="0.0090047279370085 0.0111852451755397 0.106600001456755" rpy="-3.14159261235148 -1.5707962257303 3.14159261235148"/>
  </joint>
  <joint name="middle_joint1" type="revolute">
    <limit effort="0.0" velocity="10.0" lower="0.0" upper="1.5708"/>
    <parent link="middle_link0"/>
    <child link="middle_link1"/>
    <axis xyz=" 0. 1.  0."/>
    <origin xyz="0.0110649989310237 0.0 -0.00149999999999987" rpy="0.0 -0.0 0.0"/>
  </joint>
  <joint name="middle_joint2" type="revolute">
    <limit effort="0.0" velocity="10.0" lower="0.0" upper="1.5708"/>
    <parent link="middle_link1"/>
    <child link="middle_link2"/>
    <axis xyz=" 0. 1.  0."/>
    <origin xyz="0.0340000000000001 0.0 0.0" rpy="0.0 -0.0 0.0"/>
  </joint>
  <joint name="middle_joint3" type="revolute">
    <limit effort="0.0" velocity="10.0" lower="0.0" upper="1.5708"/>
    <parent link="middle_link2"/>
    <child link="middle_link3"/>
    <axis xyz=" 0. 1.  0."/>
    <origin xyz="0.023 0.0 0.0" rpy="0.0 -0.0 0.0"/>
  </joint>
  <joint name="ring_joint0" type="revolute">
    <limit effort="0.0" velocity="6.545" lower="-1.2217" upper="0.0"/>
    <parent link="hand_link"/>
    <child link="ring_link0"/>
    <axis xyz=" 0.  0. 1."/>
    <origin xyz="0.00900472844061551 -0.00681475347135928 0.101599999120763" rpy="-3.14159261318465 -1.5707962257303 3.14159261318465"/>
  </joint>
  <joint name="ring_joint1" type="revolute">
    <limit effort="0.0" velocity="10.0" lower="0.0" upper="1.5708"/>
    <parent link="ring_link0"/>
    <child link="ring_link1"/>
    <axis xyz=" 0. 1.  0."/>
    <origin xyz="0.011065001267014 9.99992660938361e-05 -0.00150000000000004" rpy="0.0 -0.0 0.0"/>
  </joint>
  <joint name="ring_joint2" type="revolute">
    <limit effort="0.0" velocity="10.0" lower="0.0" upper="1.5708"/>
    <parent link="ring_link1"/>
    <child link="ring_link2"/>
    <axis xyz=" 0. 1.  0."/>
    <origin xyz="0.034 0.0 0.0" rpy="0.0 -0.0 0.0"/>
  </joint>
  <joint name="ring_joint3" type="revolute">
    <limit effort="0.0" velocity="10.0" lower="0.0" upper="1.5708"/>
    <parent link="ring_link2"/>
    <child link="ring_link3"/>
    <axis xyz=" 0. 1.  0."/>
    <origin xyz="0.0230000000000001 0.0 0.0" rpy="0.0 -0.0 0.0"/>
  </joint>
  <joint name="little_joint0" type="revolute">
    <limit effort="0.0" velocity="6.545" lower="-1.2217" upper="0.0"/>
    <parent link="hand_link"/>
    <child link="little_link0"/>
    <axis xyz=" 0.  0. 1."/>
    <origin xyz="0.00900472894422229 -0.0248147534713593 0.0965999991207631" rpy="-3.14159260409306 -1.57079622683487 3.14159260409306"/>
  </joint>
  <joint name="little_joint1" type="revolute">
    <limit effort="0.0" velocity="10.0" lower="0.0" upper="1.5708"/>
    <parent link="little_link0"/>
    <child link="little_link1"/>
    <axis xyz="0. 1. 0."/>
    <origin xyz="0.0110650012670137 9.99992660936123e-05 -0.0015" rpy="0.0 -0.0 0.0"/>
  </joint>
  <joint name="little_joint2" type="revolute">
    <limit effort="0.0" velocity="10.0" lower="0.0" upper="1.5708"/>
    <parent link="little_link1"/>
    <child link="little_link2"/>
    <axis xyz="0. 1. 0."/>
    <origin xyz="0.023 0.0 0.0" rpy="0.0 -0.0 0.0"/>
  </joint>
  <joint name="little_joint3" type="revolute">
    <limit effort="0.0" velocity="10.0" lower="0.0" upper="1.5708"/>
    <parent link="little_link2"/>
    <child link="little_link3"/>
    <axis xyz="0. 1. 0."/>
    <origin xyz="0.023 0.0 0.0" rpy="0.0 -0.0 0.0"/>
  </joint>
  <material name="">
    <color rgba="0.75294118 0.75294118 0.75294118 1.        "/>
  </material>
</robot>
