<?xml version="1.0" encoding="utf-8"?>
<!-- This URDF was automatically created by SolidWorks to URDF Exporter! Originally created by Stephen Brawner (brawner@gmail.com) 
     Commit Version: 1.6.1-8-g78fed4e-dirty  Build Version: 1.6.8749.33079
     For more information, please see http://wiki.ros.org/sw_urdf_exporter -->
<robot
  name="hand_v3_model">
  <link
    name="base_link">
    <inertial>
      <origin
        xyz="-0.0159368448712576 0.000289702026784673 0.0253395763176757"
        rpy="0 0 0" />
      <mass
        value="0.185756222335551" />
      <inertia
        ixx="0.000113540618351959"
        ixy="-2.50867366425369E-07"
        ixz="1.61558068388728E-06"
        iyy="8.83117378270966E-05"
        iyz="1.59185421854018E-08"
        izz="0.000173634364629917" />
    </inertial>
    <visual>
      <origin
        xyz="0 0 0"
        rpy="0 0 0" />
      <geometry>
        <mesh
          filename="package://hand_v3_model/meshes/base_link.3dxml" />
      </geometry>
      <material
        name="">
        <color
          rgba="0.752941176470588 0.752941176470588 0.752941176470588 1" />
      </material>
    </visual>
    <collision>
      <origin
        xyz="0 0 0"
        rpy="0 0 0" />
      <geometry>
        <mesh
          filename="package://hand_v3_model/meshes/base_link.3dxml" />
      </geometry>
    </collision>
  </link>
  <link
    name="arm_link1">
    <inertial>
      <origin
        xyz="-0.00978848438025783 0.000384177196331765 -0.0621576063561142"
        rpy="0 0 0" />
      <mass
        value="0.193074721865222" />
      <inertia
        ixx="3.80213740266299E-05"
        ixy="-2.21684269435204E-06"
        ixz="-1.00323348399987E-08"
        iyy="4.53666816375235E-05"
        iyz="-3.12451267361753E-08"
        izz="5.42874707579927E-05" />
    </inertial>
    <visual>
      <origin
        xyz="-1.21797336860599E-14 1.09007835125724E-14 -0.0710000000000039"
        rpy="0 0 0" />
      <geometry>
        <mesh
          filename="package://hand_v3_model/meshes/arm_link1.3dxml" />
      </geometry>
      <material
        name="">
        <color
          rgba="0.752941176470588 0.752941176470588 0.752941176470588 1" />
      </material>
    </visual>
    <collision>
      <origin
        xyz="-1.21797336860599E-14 1.09007835125724E-14 -0.0710000000000039"
        rpy="0 0 0" />
      <geometry>
        <mesh
          filename="package://hand_v3_model/meshes/arm_link1.3dxml" />
      </geometry>
    </collision>
  </link>
  <joint
    name="arm_joint0"
    type="revolute">
    <origin
      xyz="0 0 0.0710000000000039"
      rpy="0 0 0" />
    <parent
      link="base_link" />
    <child
      link="arm_link1" />
    <axis
      xyz="0 -1 0" />
    <limit
      lower="-2.06167"
      upper="0.41233"
      effort="0"
      velocity="4.553" />
  </joint>
  <link
    name="arm_link2">
    <inertial>
      <origin
        xyz="4.83407049837964E-05 5.06154260248703E-05 -0.0995489576359955"
        rpy="0 0 0" />
      <mass
        value="0.0413445310117904" />
      <inertia
        ixx="6.13742631381391E-06"
        ixy="-1.14668747691786E-08"
        ixz="-3.13675118837437E-09"
        iyy="5.39269102743716E-06"
        iyz="-1.89827016745712E-08"
        izz="3.76704222934287E-06" />
    </inertial>
    <visual>
      <origin
        xyz="-1.23408346606709E-14 2.13996621527825E-14 -0.141700000000004"
        rpy="0 0 0" />
      <geometry>
        <mesh
          filename="package://hand_v3_model/meshes/arm_link2.3dxml" />
      </geometry>
      <material
        name="">
        <color
          rgba="0.752941176470588 0.752941176470588 0.752941176470588 1" />
      </material>
    </visual>
    <collision>
      <origin
        xyz="-1.23408346606709E-14 2.13996621527825E-14 -0.141700000000004"
        rpy="0 0 0" />
      <geometry>
        <mesh
          filename="package://hand_v3_model/meshes/arm_link2.3dxml" />
      </geometry>
    </collision>
  </link>
  <joint
    name="arm_joint1"
    type="revolute">
    <origin
      xyz="0 0 0.0707"
      rpy="0 0 0" />
    <parent
      link="arm_link1" />
    <child
      link="arm_link2" />
    <axis
      xyz="0 0 1" />
    <limit
      lower="-2.3562"
      upper="2.3562"
      effort="0"
      velocity="6.545" />
  </joint>
  <link
    name="arm_link3">
    <inertial>
      <origin
        xyz="-7.32385338863604E-05 0.000168976972247172 -0.177623391706597"
        rpy="0 0 0" />
      <mass
        value="0.0285401131313353" />
      <inertia
        ixx="3.28801768228182E-06"
        ixy="1.14697545620646E-08"
        ixz="1.89840699729582E-08"
        iyy="3.41808882123853E-06"
        iyz="-6.70904151464841E-09"
        izz="2.74702490399628E-06" />
    </inertial>
    <visual>
      <origin
        xyz="-1.36338070770796E-14 2.10989116680624E-14 -0.210700000000004"
        rpy="0 0 0" />
      <geometry>
        <mesh
          filename="package://hand_v3_model/meshes/arm_link3.3dxml" />
      </geometry>
      <material
        name="">
        <color
          rgba="0.752941176470588 0.752941176470588 0.752941176470588 1" />
      </material>
    </visual>
    <collision>
      <origin
        xyz="-1.36338070770796E-14 2.10989116680624E-14 -0.210700000000004"
        rpy="0 0 0" />
      <geometry>
        <mesh
          filename="package://hand_v3_model/meshes/arm_link3.3dxml" />
      </geometry>
    </collision>
  </link>
  <joint
    name="arm_joint2"
    type="revolute">
    <origin
      xyz="0 0 0.069"
      rpy="0 0 0" />
    <parent
      link="arm_link2" />
    <child
      link="arm_link3" />
    <axis
      xyz="0 -1 0" />
    <limit
      lower="-1.5708"
      upper="0.06"
      effort="0"
      velocity="6.545" />
  </joint>
  <link
    name="hand_link">
    <inertial>
      <origin
        xyz="0.00239249532730597 -0.000454670310455432 -0.198061785013894"
        rpy="0 0 0" />
      <mass
        value="0.0862355112971162" />
      <inertia
        ixx="1.21593177078041E-05"
        ixy="-6.20382094262845E-08"
        ixz="-3.92636544873787E-08"
        iyy="5.80978848403572E-06"
        iyz="3.49334419785276E-07"
        izz="1.15352340969383E-05" />
    </inertial>
    <visual>
      <origin
        xyz="-1.07485432813368E-14 2.1597072595029E-14 -0.257700000000001"
        rpy="0 0 0" />
      <geometry>
        <mesh
          filename="package://hand_v3_model/meshes/hand_link.3dxml" />
      </geometry>
      <material
        name="">
        <color
          rgba="0.752941176470588 0.752941176470588 0.752941176470588 1" />
      </material>
    </visual>
    <collision>
      <origin
        xyz="-1.07485432813368E-14 2.1597072595029E-14 -0.257700000000001"
        rpy="0 0 0" />
      <geometry>
        <mesh
          filename="package://hand_v3_model/meshes/hand_link.3dxml" />
      </geometry>
    </collision>
  </link>
  <joint
    name="hand_base_joint"
    type="revolute">
    <origin
      xyz="0 0 0.046999999999997"
      rpy="0 0 0" />
    <parent
      link="arm_link3" />
    <child
      link="hand_link" />
    <axis
      xyz="-1 0 0" />
    <limit
      lower="-1.5708"
      upper="1.5708"
      effort="0"
      velocity="6.545" />
  </joint>
  <link
    name="thumb_pulley_link">
    <inertial>
      <origin
        xyz="0.00499396665093409 -0.0288234692035366 0.300540813255855"
        rpy="0 0 0" />
      <mass
        value="0.000573068394145989" />
      <inertia
        ixx="1.01383604562528E-08"
        ixy="2.14620718289238E-10"
        ixz="6.10690723533873E-12"
        iyy="1.04389572865727E-08"
        iyz="-1.17292338601506E-11"
        izz="1.95368356803049E-08" />
    </inertial>
    <visual>
      <origin
        xyz="0.00510473038958318 -0.0290362596907637 0.299200005856291"
        rpy="3.14159265358979 0 3.14159265358979" />
      <geometry>
        <mesh
          filename="package://hand_v3_model/meshes/thumb_pulley_link.3dxml" />
      </geometry>
      <material
        name="">
        <color
          rgba="0 0 0 1" />
      </material>
    </visual>
    <collision>
      <origin
        xyz="0.00510473038958318 -0.0290362596907637 0.299200005856291"
        rpy="3.14159265358979 0 3.14159265358979" />
      <geometry>
        <mesh
          filename="package://hand_v3_model/meshes/thumb_pulley_link.3dxml" />
      </geometry>
    </collision>
  </link>
  <joint
    name="thumb_pulley_joint"
    type="continuous">
    <origin
      xyz="0.00510473038957243 0.0290362596907853 0.0415000058562903"
      rpy="3.14159265358979 0 3.14159265358979" />
    <parent
      link="hand_link" />
    <child
      link="thumb_pulley_link" />
    <axis
      xyz="0 0 0.999999999999954" />
    <limit
      effort="0"
      velocity="10" />
  </joint>
  <link
    name="index_pulley_link">
    <inertial>
      <origin
        xyz="0.0104400800960098 0.0260043933773204 0.338052915986819"
        rpy="0 0 0" />
      <mass
        value="0.00101512886583035" />
      <inertia
        ixx="5.80350843229943E-08"
        ixy="1.70386993085394E-11"
        ixz="3.48093654518268E-12"
        iyy="3.04025634559552E-08"
        iyz="-2.09219414876704E-10"
        izz="2.94212062442424E-08" />
    </inertial>
    <visual>
      <origin
        xyz="0.00909526961041773 0.0262348940717034 0.338100006335385"
        rpy="3.14159265358979 1.30921128989166E-15 0" />
      <geometry>
        <mesh
          filename="package://hand_v3_model/meshes/index_pulley_link.3dxml" />
      </geometry>
      <material
        name="">
        <color
          rgba="0 0 0 1" />
      </material>
    </visual>
    <collision>
      <origin
        xyz="0.00909526961041773 0.0262348940717034 0.338100006335385"
        rpy="3.14159265358979 1.30921128989166E-15 0" />
      <geometry>
        <mesh
          filename="package://hand_v3_model/meshes/index_pulley_link.3dxml" />
      </geometry>
    </collision>
  </link>
  <joint
    name="index_pulley_joint"
    type="continuous">
    <origin
      xyz="-0.00909526961042804 0.026234894071725 0.080400006335384"
      rpy="3.14159265358979 0 0" />
    <parent
      link="hand_link" />
    <child
      link="index_pulley_link" />
    <axis
      xyz="1 0 0" />
    <limit
      effort="0"
      velocity="10" />
  </joint>
  <link
    name="middle_pulley_link">
    <inertial>
      <origin
        xyz="0.00750536511192664 0.0104854577895602 0.346062202823937"
        rpy="0 0 0" />
      <mass
        value="0.00126450613447782" />
      <inertia
        ixx="6.15321269949602E-08"
        ixy="1.7270734870826E-10"
        ixz="3.52834045616528E-11"
        iyy="3.46243381639731E-08"
        iyz="-2.07046407283457E-10"
        izz="3.36531735850713E-08" />
    </inertial>
    <visual>
      <origin
        xyz="0.00909526961041802 0.0106705007103382 0.346100006335385"
        rpy="3.14159265358979 1.91588950893966E-15 0" />
      <geometry>
        <mesh
          filename="package://hand_v3_model/meshes/middle_pulley_link.3dxml" />
      </geometry>
      <material
        name="">
        <color
          rgba="0 0 0 1" />
      </material>
    </visual>
    <collision>
      <origin
        xyz="0.00909526961041802 0.0106705007103382 0.346100006335385"
        rpy="3.14159265358979 1.91588950893966E-15 0" />
      <geometry>
        <mesh
          filename="package://hand_v3_model/meshes/middle_pulley_link.3dxml" />
      </geometry>
    </collision>
  </link>
  <joint
    name="middle_pulley_joint"
    type="continuous">
    <origin
      xyz="-0.0090952696104281 0.0106705007103598 0.088400006335384"
      rpy="3.14159265358979 0 0" />
    <parent
      link="hand_link" />
    <child
      link="middle_pulley_link" />
    <axis
      xyz="-1 0 0" />
    <limit
      effort="0"
      velocity="10" />
  </joint>
  <link
    name="ring_pulley_link">
    <inertial>
      <origin
        xyz="0.0104400800960335 -0.00633049887020139 0.341052909651437"
        rpy="0 0 0" />
      <mass
        value="0.00101512886583036" />
      <inertia
        ixx="5.80350843229944E-08"
        ixy="1.7038699308586E-11"
        ixz="3.48093654518006E-12"
        iyy="3.04025634559552E-08"
        iyz="-2.09219414876704E-10"
        izz="2.94212062442424E-08" />
    </inertial>
    <visual>
      <origin
        xyz="0.00909526961041822 -0.00609999817581914 0.341100000000002"
        rpy="3.14159265358979 2.58574932440018E-15 0" />
      <geometry>
        <mesh
          filename="package://hand_v3_model/meshes/ring_pulley_link.3dxml" />
      </geometry>
      <material
        name="">
        <color
          rgba="0 0 0 1" />
      </material>
    </visual>
    <collision>
      <origin
        xyz="0.00909526961041822 -0.00609999817581914 0.341100000000002"
        rpy="3.14159265358979 2.58574932440018E-15 0" />
      <geometry>
        <mesh
          filename="package://hand_v3_model/meshes/ring_pulley_link.3dxml" />
      </geometry>
    </collision>
  </link>
  <joint
    name="ring_pulley_joint"
    type="continuous">
    <origin
      xyz="-0.00909526961042809 -0.00609999817579755 0.0834000000000015"
      rpy="3.14159265358979 0 0" />
    <parent
      link="hand_link" />
    <child
      link="ring_pulley_link" />
    <axis
      xyz="-1 0 0" />
    <limit
      effort="0"
      velocity="10" />
  </joint>
  <link
    name="little_pulley_link">
    <inertial>
      <origin
        xyz="0.0075053651119492 -0.0218312316345219 0.333011508657783"
        rpy="0 0 0" />
      <mass
        value="0.00126450613447782" />
      <inertia
        ixx="6.15321269949601E-08"
        ixy="1.55728201033398E-10"
        ixz="8.25922171814842E-11"
        iyy="3.44348629344565E-08"
        iyz="-4.37011422796308E-10"
        izz="3.3842648814588E-08" />
    </inertial>
    <visual>
      <origin
        xyz="0.00909526961041816 -0.0216643805920936 0.333100000000003"
        rpy="3.14159265358979 2.66453525910038E-15 0" />
      <geometry>
        <mesh
          filename="package://hand_v3_model/meshes/little_pulley_link.3dxml" />
      </geometry>
      <material
        name="">
        <color
          rgba="0 0 0 1" />
      </material>
    </visual>
    <collision>
      <origin
        xyz="0.00909526961041816 -0.0216643805920936 0.333100000000003"
        rpy="3.14159265358979 2.66453525910038E-15 0" />
      <geometry>
        <mesh
          filename="package://hand_v3_model/meshes/little_pulley_link.3dxml" />
      </geometry>
    </collision>
  </link>
  <joint
    name="little_pulley_joint"
    type="continuous">
    <origin
      xyz="-0.00909526961042802 -0.021664380592072 0.0754000000000016"
      rpy="3.14159265358979 0 0" />
    <parent
      link="hand_link" />
    <child
      link="little_pulley_link" />
    <axis
      xyz="-1 0 0" />
    <limit
      effort="0"
      velocity="10" />
  </joint>
  <link
    name="adduction_pulley_link">
    <inertial>
      <origin
        xyz="-0.000393846214060233 -0.00427523428694994 -0.297632293965204"
        rpy="0 0 0" />
      <mass
        value="0.001757686295804" />
      <inertia
        ixx="3.85008956769593E-08"
        ixy="1.17217652597688E-11"
        ixz="-6.36420221979036E-10"
        iyy="7.13845589903268E-08"
        iyz="5.36365951738641E-12"
        izz="3.74012740005429E-08" />
    </inertial>
    <visual>
      <origin
        xyz="-0.000104730389583172 -0.00328525673980379 -0.297500000000002"
        rpy="0 0 0" />
      <geometry>
        <mesh
          filename="package://hand_v3_model/meshes/adduction_pulley_link.3dxml" />
      </geometry>
      <material
        name="">
        <color
          rgba="0.298039215686275 0.298039215686275 0.298039215686275 1" />
      </material>
    </visual>
    <collision>
      <origin
        xyz="-0.000104730389583172 -0.00328525673980379 -0.297500000000002"
        rpy="0 0 0" />
      <geometry>
        <mesh
          filename="package://hand_v3_model/meshes/adduction_pulley_link.3dxml" />
      </geometry>
    </collision>
  </link>
  <joint
    name="adduction_pulley_joint"
    type="continuous">
    <origin
      xyz="0.000104730389572423 0.00328525673982538 0.0398000000000016"
      rpy="0 0 0" />
    <parent
      link="hand_link" />
    <child
      link="adduction_pulley_link" />
    <axis
      xyz="0 1 0" />
    <limit
      effort="0"
      velocity="6.545" />
  </joint>
  <link
    name="thumb_link0">
    <inertial>
      <origin
        xyz="-0.0131984273671712 -0.00725706379200231 -0.291061834200039"
        rpy="0 0 0" />
      <mass
        value="0.00222751592226221" />
      <inertia
        ixx="2.3888924629314E-07"
        ixy="1.99935318163553E-09"
        ixz="-6.52098353684233E-10"
        iyy="9.11947268793252E-08"
        iyz="6.66199427254774E-08"
        izz="1.73153324814096E-07" />
    </inertial>
    <visual>
      <origin
        xyz="-0.0131047303895831 -0.0212852595376459 -0.301300003304203"
        rpy="0 0 0" />
      <geometry>
        <mesh
          filename="package://hand_v3_model/meshes/thumb_link0.3dxml" />
      </geometry>
      <material
        name="">
        <color
          rgba="1 1 1 1" />
      </material>
    </visual>
    <collision>
      <origin
        xyz="-0.0131047303895831 -0.0212852595376459 -0.301300003304203"
        rpy="0 0 0" />
      <geometry>
        <mesh
          filename="package://hand_v3_model/meshes/thumb_link0.3dxml" />
      </geometry>
    </collision>
  </link>
  <joint
    name="thumb_joint0"
    type="revolute">
    <origin
      xyz="0.0131047303895724 0.0212852595376675 0.0436000033042019"
      rpy="0 0 0" />
    <parent
      link="hand_link" />
    <child
      link="thumb_link0" />
    <axis
      xyz="0 0 -0.999999999999985" />
    <limit
      lower="0"
      upper="2.0944"
      effort="0"
      velocity="10" />
  </joint>
  <link
    name="thumb_link1">
    <inertial>
      <origin
        xyz="-0.296479123494841 0.0965415981316485 0.098643793725724"
        rpy="0 0 0" />
      <mass
        value="0.00165203073265575" />
      <inertia
        ixx="1.28625246386984E-07"
        ixy="-4.60513608382968E-09"
        ixz="-1.29650086921569E-08"
        iyy="9.85847874936955E-08"
        iyz="4.44238701248018E-08"
        izz="5.69370799493245E-08" />
    </inertial>
    <visual>
      <origin
        xyz="-0.295602266948084 0.0904879645075565 0.110163941716504"
        rpy="2.34172725852824 1.03834412827171 1.81671012667268" />
      <geometry>
        <mesh
          filename="package://hand_v3_model/meshes/thumb_link1.3dxml" />
      </geometry>
      <material
        name="">
        <color
          rgba="0.752941176470588 0.752941176470588 0.752941176470588 1" />
      </material>
    </visual>
    <collision>
      <origin
        xyz="-0.295602266948084 0.0904879645075565 0.110163941716504"
        rpy="2.34172725852824 1.03834412827171 1.81671012667268" />
      <geometry>
        <mesh
          filename="package://hand_v3_model/meshes/thumb_link1.3dxml" />
      </geometry>
    </collision>
  </link>
  <joint
    name="thumb_joint1"
    type="revolute">
    <origin
      xyz="0.00072316968380136 0.0243257662747911 0.0234049235201093"
      rpy="-2.28547286926153 -1.0006691861817 1.80181397893486" />
    <parent
      link="thumb_link0" />
    <child
      link="thumb_link1" />
    <axis
      xyz="0 -1 0" />
    <limit
      lower="0"
      upper="1.5708"
      effort="0"
      velocity="10" />
  </joint>
  <link
    name="thumb_link2">
    <inertial>
      <origin
        xyz="-0.323396126487467 0.0939104839174868 0.102638221515411"
        rpy="0 0 0" />
      <mass
        value="0.00106407341908137" />
      <inertia
        ixx="5.01077093105504E-08"
        ixy="-2.93123438162397E-09"
        ixz="-7.12065285952429E-09"
        iyy="3.84021169917255E-08"
        iyz="1.6054620341175E-08"
        izz="2.71055509753875E-08" />
    </inertial>
    <visual>
      <origin
        xyz="-0.323602266948084 0.0904879645075558 0.110163941716505"
        rpy="2.34172725852824 1.03834412827171 1.81671012667268" />
      <geometry>
        <mesh
          filename="package://hand_v3_model/meshes/thumb_link2.3dxml" />
      </geometry>
      <material
        name="">
        <color
          rgba="0.752941176470588 0.752941176470588 0.752941176470588 1" />
      </material>
    </visual>
    <collision>
      <origin
        xyz="-0.323602266948084 0.0904879645075558 0.110163941716505"
        rpy="2.34172725852824 1.03834412827171 1.81671012667268" />
      <geometry>
        <mesh
          filename="package://hand_v3_model/meshes/thumb_link2.3dxml" />
      </geometry>
    </collision>
  </link>
  <joint
    name="thumb_joint2"
    type="revolute">
    <origin
      xyz="0.0279999999999995 0 0"
      rpy="0 0 0" />
    <parent
      link="thumb_link1" />
    <child
      link="thumb_link2" />
    <axis
      xyz="0 -1 0" />
    <limit
      lower="0"
      upper="1.5708"
      effort="0"
      velocity="10" />
  </joint>
  <link
    name="index_link0">
    <inertial>
      <origin
        xyz="-0.358246589723696 -0.0296537586327549 0.00456477436993843"
        rpy="0 0 0" />
      <mass
        value="0.000862118530230645" />
      <inertia
        ixx="2.74838732877092E-08"
        ixy="4.60249360851945E-11"
        ixz="1.64629832322558E-09"
        iyy="2.4815764455565E-08"
        iyz="-2.9337068423474E-10"
        izz="1.83260236280527E-08" />
    </inertial>
    <visual>
      <origin
        xyz="-0.358299998213794 -0.0292852465286189 0.00900476462980921"
        rpy="-3.14159264884631 1.5707962257303 -3.14159264884631" />
      <geometry>
        <mesh
          filename="package://hand_v3_model/meshes/index_link0.3dxml" />
      </geometry>
      <material
        name="">
        <color
          rgba="0.792156862745098 0.819607843137255 0.933333333333333 1" />
      </material>
    </visual>
    <collision>
      <origin
        xyz="-0.358299998213794 -0.0292852465286189 0.00900476462980921"
        rpy="-3.14159264884631 1.5707962257303 -3.14159264884631" />
      <geometry>
        <mesh
          filename="package://hand_v3_model/meshes/index_link0.3dxml" />
      </geometry>
    </collision>
  </link>
  <joint
    name="index_joint0"
    type="revolute">
    <origin
      xyz="0.00900472854133688 0.0292852465286407 0.100599999120763"
      rpy="-3.14159264732828 -1.5707962257303 3.14159264732828" />
    <parent
      link="hand_link" />
    <child
      link="index_link0" />
    <axis
      xyz="0 0 -0.999999999999985" />
    <limit
      lower="0"
      upper="1.2217"
      effort="0"
      velocity="6.545" />
  </joint>
  <link
    name="index_link1">
    <inertial>
      <origin
        xyz="-0.368496020562021 -0.0291853153023425 -0.00250964222369502"
        rpy="0 0 0" />
      <mass
        value="0.00165203434128294" />
      <inertia
        ixx="1.32129915581458E-07"
        ixy="-6.62321335808929E-13"
        ixz="-8.88666584045425E-10"
        iyy="1.25083225521205E-07"
        iyz="-1.81097402604625E-12"
        izz="2.69357717030325E-08" />
    </inertial>
    <visual>
      <origin
        xyz="-0.369364999480807 -0.0291852457947127 0.0105047646298093"
        rpy="-3.14159264406214 1.5707962257303 -3.14159264406214" />
      <geometry>
        <mesh
          filename="package://hand_v3_model/meshes/index_link1.3dxml" />
      </geometry>
      <material
        name="">
        <color
          rgba="0.752941176470588 0.752941176470588 0.752941176470588 1" />
      </material>
    </visual>
    <collision>
      <origin
        xyz="-0.369364999480807 -0.0291852457947127 0.0105047646298093"
        rpy="-3.14159264406214 1.5707962257303 -3.14159264406214" />
      <geometry>
        <mesh
          filename="package://hand_v3_model/meshes/index_link1.3dxml" />
      </geometry>
    </collision>
  </link>
  <joint
    name="index_joint1"
    type="revolute">
    <origin
      xyz="0.0110650012670139 -0.000100000733906178 -0.00150000000000009"
      rpy="0 0 0" />
    <parent
      link="index_link0" />
    <child
      link="index_link1" />
    <axis
      xyz="0 -1 0" />
    <limit
      lower="0"
      upper="1.5708"
      effort="0"
      velocity="10" />
  </joint>
  <link
    name="index_link2">
    <inertial>
      <origin
        xyz="-0.396507626849074 -0.0291853490981649 -1.4064543966073E-05"
        rpy="0 0 0" />
      <mass
        value="0.00138867181880575" />
      <inertia
        ixx="8.3179130954676E-08"
        ixy="-7.83803287508677E-13"
        ixz="-8.1545223384782E-10"
        iyy="7.7708847768507E-08"
        iyz="-1.730770425077E-12"
        izz="2.23707352283301E-08" />
    </inertial>
    <visual>
      <origin
        xyz="-0.397364999480808 -0.0291852457947131 0.0105047646298092"
        rpy="-3.1415926456317 1.5707962257303 -3.1415926456317" />
      <geometry>
        <mesh
          filename="package://hand_v3_model/meshes/index_link2.3dxml" />
      </geometry>
      <material
        name="">
        <color
          rgba="0.752941176470588 0.752941176470588 0.752941176470588 1" />
      </material>
    </visual>
    <collision>
      <origin
        xyz="-0.397364999480808 -0.0291852457947131 0.0105047646298092"
        rpy="-3.1415926456317 1.5707962257303 -3.1415926456317" />
      <geometry>
        <mesh
          filename="package://hand_v3_model/meshes/index_link2.3dxml" />
      </geometry>
    </collision>
  </link>
  <joint
    name="index_joint2"
    type="revolute">
    <origin
      xyz="0.028 0 0"
      rpy="0 0 0" />
    <parent
      link="index_link1" />
    <child
      link="index_link2" />
    <axis
      xyz="0 -1 0" />
    <limit
      lower="0"
      upper="1.5708"
      effort="0"
      velocity="10" />
  </joint>
  <link
    name="index_link3">
    <inertial>
      <origin
        xyz="-0.418924246785047 -0.0291851992926505 0.00235918931256635"
        rpy="0 0 0" />
      <mass
        value="0.0010642513972353" />
      <inertia
        ixx="5.23369094826426E-08"
        ixy="-3.35288480460072E-13"
        ixz="-3.64395617545436E-09"
        iyy="4.88130690506473E-08"
        iyz="5.94614647011101E-13"
        izz="1.45125530907261E-08" />
    </inertial>
    <visual>
      <origin
        xyz="-0.420364999480808 -0.0291852457947134 0.0105047646298092"
        rpy="-3.1415926460144 1.5707962257303 -3.1415926460144" />
      <geometry>
        <mesh
          filename="package://hand_v3_model/meshes/index_link3.3dxml" />
      </geometry>
      <material
        name="">
        <color
          rgba="0.752941176470588 0.752941176470588 0.752941176470588 1" />
      </material>
    </visual>
    <collision>
      <origin
        xyz="-0.420364999480808 -0.0291852457947134 0.0105047646298092"
        rpy="-3.1415926460144 1.5707962257303 -3.1415926460144" />
      <geometry>
        <mesh
          filename="package://hand_v3_model/meshes/index_link3.3dxml" />
      </geometry>
    </collision>
  </link>
  <joint
    name="index_joint3"
    type="revolute">
    <origin
      xyz="0.023 0 0"
      rpy="0 0 0" />
    <parent
      link="index_link2" />
    <child
      link="index_link3" />
    <axis
      xyz="0 -1 0" />
    <limit
      lower="0"
      upper="1.5708"
      effort="0"
      velocity="10" />
  </joint>
  <link
    name="middle_link0">
    <inertial>
      <origin
        xyz="-0.364246615288256 -0.0114537386699524 0.00457789737568003"
        rpy="0 0 0" />
      <mass
        value="0.000862150655926043" />
      <inertia
        ixx="2.74370185779519E-08"
        ixy="4.61263021077474E-11"
        ixz="1.63570678602322E-09"
        iyy="2.47678482511169E-08"
        iyz="-3.62922479724337E-10"
        izz="1.83271437549206E-08" />
    </inertial>
    <visual>
      <origin
        xyz="-0.364300000549786 -0.0111852451755166 0.00900476462980938"
        rpy="3.14159265128834 1.5707962257303 3.14159265128833" />
      <geometry>
        <mesh
          filename="package://hand_v3_model/meshes/middle_link0.3dxml" />
      </geometry>
      <material
        name="">
        <color
          rgba="0.792156862745098 0.819607843137255 0.933333333333333 1" />
      </material>
    </visual>
    <collision>
      <origin
        xyz="-0.364300000549786 -0.0111852451755166 0.00900476462980938"
        rpy="3.14159265128834 1.5707962257303 3.14159265128833" />
      <geometry>
        <mesh
          filename="package://hand_v3_model/meshes/middle_link0.3dxml" />
      </geometry>
    </collision>
  </link>
  <joint
    name="middle_joint0"
    type="revolute">
    <origin
      xyz="0.0090047279370085 0.0111852451755397 0.106600001456755"
      rpy="-3.14159261235148 -1.5707962257303 3.14159261235148" />
    <parent
      link="hand_link" />
    <child
      link="middle_link0" />
    <axis
      xyz="0 0 0.999999999999985" />
    <limit
      lower="0"
      upper="1.2217"
      effort="0"
      velocity="6.545" />
  </joint>
  <link
    name="middle_link1">
    <inertial>
      <origin
        xyz="-0.374466227181728 -0.0111852850134854 -0.00545182219025148"
        rpy="0 0 0" />
      <mass
        value="0.00195707994885378" />
      <inertia
        ixx="2.13983170855394E-07"
        ixy="-4.80398266291894E-13"
        ixz="-1.32901123014075E-09"
        iyy="2.04977420227209E-07"
        iyz="-1.72954876503655E-12"
        izz="3.21864462364343E-08" />
    </inertial>
    <visual>
      <origin
        xyz="-0.37536499948081 -0.0111852457947112 0.0105047646298094"
        rpy="3.14159265236924 1.5707962257303 3.14159265236923" />
      <geometry>
        <mesh
          filename="package://hand_v3_model/meshes/middle_link1.3dxml" />
      </geometry>
      <material
        name="">
        <color
          rgba="0.752941176470588 0.752941176470588 0.752941176470588 1" />
      </material>
    </visual>
    <collision>
      <origin
        xyz="-0.37536499948081 -0.0111852457947112 0.0105047646298094"
        rpy="3.14159265236924 1.5707962257303 3.14159265236923" />
      <geometry>
        <mesh
          filename="package://hand_v3_model/meshes/middle_link1.3dxml" />
      </geometry>
    </collision>
  </link>
  <joint
    name="middle_joint1"
    type="revolute">
    <origin
      xyz="0.0110649989310237 0 -0.00149999999999987"
      rpy="0 0 0" />
    <parent
      link="middle_link0" />
    <child
      link="middle_link1" />
    <axis
      xyz="0 -1 0" />
    <limit
      lower="0"
      upper="1.5708"
      effort="0"
      velocity="10" />
  </joint>
  <link
    name="middle_link2">
    <inertial>
      <origin
        xyz="-0.408507626849092 -0.0111853490981735 -1.40645439640121E-05"
        rpy="0 0 0" />
      <mass
        value="0.00138867181880573" />
      <inertia
        ixx="8.31791309546753E-08"
        ixy="-7.83803287530291E-13"
        ixz="-8.15452233848222E-10"
        iyy="7.77088477685063E-08"
        iyz="-1.73077042527186E-12"
        izz="2.23707352283299E-08" />
    </inertial>
    <visual>
      <origin
        xyz="-0.40936499948081 -0.0111852457947114 0.0105047646298094"
        rpy="-3.1415926517105 1.5707962257303 -3.1415926517105" />
      <geometry>
        <mesh
          filename="package://hand_v3_model/meshes/middle_link2.3dxml" />
      </geometry>
      <material
        name="">
        <color
          rgba="0.752941176470588 0.752941176470588 0.752941176470588 1" />
      </material>
    </visual>
    <collision>
      <origin
        xyz="-0.40936499948081 -0.0111852457947114 0.0105047646298094"
        rpy="-3.1415926517105 1.5707962257303 -3.1415926517105" />
      <geometry>
        <mesh
          filename="package://hand_v3_model/meshes/middle_link2.3dxml" />
      </geometry>
    </collision>
  </link>
  <joint
    name="middle_joint2"
    type="revolute">
    <origin
      xyz="0.0340000000000001 0 0"
      rpy="0 0 0" />
    <parent
      link="middle_link1" />
    <child
      link="middle_link2" />
    <axis
      xyz="0 -1 0" />
    <limit
      lower="0"
      upper="1.5708"
      effort="0"
      velocity="10" />
  </joint>
  <link
    name="middle_link3">
    <inertial>
      <origin
        xyz="-0.430924246785064 -0.0111851992926589 0.00235918931256839"
        rpy="0 0 0" />
      <mass
        value="0.00106425139723533" />
      <inertia
        ixx="5.23369094826472E-08"
        ixy="-3.35288480500077E-13"
        ixz="-3.64395617545474E-09"
        iyy="4.88130690506518E-08"
        iyz="5.94614647117015E-13"
        izz="1.45125530907262E-08" />
    </inertial>
    <visual>
      <origin
        xyz="-0.43236499948081 -0.0111852457947114 0.0105047646298096"
        rpy="3.14159265324505 1.57079622355662 3.14159265324505" />
      <geometry>
        <mesh
          filename="package://hand_v3_model/meshes/middle_link3.3dxml" />
      </geometry>
      <material
        name="">
        <color
          rgba="0.752941176470588 0.752941176470588 0.752941176470588 1" />
      </material>
    </visual>
    <collision>
      <origin
        xyz="-0.43236499948081 -0.0111852457947114 0.0105047646298096"
        rpy="3.14159265324505 1.57079622355662 3.14159265324505" />
      <geometry>
        <mesh
          filename="package://hand_v3_model/meshes/middle_link3.3dxml" />
      </geometry>
    </collision>
  </link>
  <joint
    name="middle_joint3"
    type="revolute">
    <origin
      xyz="0.023 0 0"
      rpy="0 0 0" />
    <parent
      link="middle_link2" />
    <child
      link="middle_link3" />
    <axis
      xyz="0 -1 0" />
    <limit
      lower="0"
      upper="1.5708"
      effort="0"
      velocity="10" />
  </joint>
  <link
    name="ring_link0">
    <inertial>
      <origin
        xyz="-0.359246592312053 0.00718323715862302 0.00457779055610991"
        rpy="0 0 0" />
      <mass
        value="0.000862141381321495" />
      <inertia
        ixx="2.74365725109563E-08"
        ixy="-4.6104654949058E-11"
        ixz="1.63564836675834E-09"
        iyy="2.47668560611884E-08"
        iyz="3.63501748154234E-10"
        izz="1.83274320135936E-08" />
    </inertial>
    <visual>
      <origin
        xyz="-0.359299998213794 0.00681475347138234 0.00900476462980948"
        rpy="3.14159265006496 1.5707962257303 3.14159265006495" />
      <geometry>
        <mesh
          filename="package://hand_v3_model/meshes/ring_link0.3dxml" />
      </geometry>
      <material
        name="">
        <color
          rgba="0.792156862745098 0.819607843137255 0.933333333333333 1" />
      </material>
    </visual>
    <collision>
      <origin
        xyz="-0.359299998213794 0.00681475347138234 0.00900476462980948"
        rpy="3.14159265006496 1.5707962257303 3.14159265006495" />
      <geometry>
        <mesh
          filename="package://hand_v3_model/meshes/ring_link0.3dxml" />
      </geometry>
    </collision>
  </link>
  <joint
    name="ring_joint0"
    type="revolute">
    <origin
      xyz="0.00900472844061551 -0.00681475347135928 0.101599999120763"
      rpy="-3.14159261318465 -1.5707962257303 3.14159261318465" />
    <parent
      link="hand_link" />
    <child
      link="ring_link0" />
    <axis
      xyz="0 0 -0.999999999999985" />
    <limit
      lower="-1.2217"
      upper="0"
      effort="0"
      velocity="6.545" />
  </joint>
  <link
    name="ring_link1">
    <inertial>
      <origin
        xyz="-0.369466227181739 0.00671471498651375 -0.00545182219025299"
        rpy="0 0 0" />
      <mass
        value="0.00195707994885374" />
      <inertia
        ixx="2.13983170855384E-07"
        ixy="-4.80398266690734E-13"
        ixz="-1.32901123014309E-09"
        iyy="2.04977420227199E-07"
        iyz="-1.72954876670285E-12"
        izz="3.21864462364331E-08" />
    </inertial>
    <visual>
      <origin
        xyz="-0.370364999480808 0.00671475420528815 0.0105047646298096"
        rpy="3.14159263674689 1.5707962257303 3.14159263674689" />
      <geometry>
        <mesh
          filename="package://hand_v3_model/meshes/ring_link1.3dxml" />
      </geometry>
      <material
        name="">
        <color
          rgba="0.752941176470588 0.752941176470588 0.752941176470588 1" />
      </material>
    </visual>
    <collision>
      <origin
        xyz="-0.370364999480808 0.00671475420528815 0.0105047646298096"
        rpy="3.14159263674689 1.5707962257303 3.14159263674689" />
      <geometry>
        <mesh
          filename="package://hand_v3_model/meshes/ring_link1.3dxml" />
      </geometry>
    </collision>
  </link>
  <joint
    name="ring_joint1"
    type="revolute">
    <origin
      xyz="0.011065001267014 9.99992660938361E-05 -0.00150000000000004"
      rpy="0 0 0" />
    <parent
      link="ring_link0" />
    <child
      link="ring_link1" />
    <axis
      xyz="0 -1 0" />
    <limit
      lower="0"
      upper="1.5708"
      effort="0"
      velocity="10" />
  </joint>
  <link
    name="ring_link2">
    <inertial>
      <origin
        xyz="-0.403507626848989 0.0067146509018258 -1.40645438526099E-05"
        rpy="0 0 0" />
      <mass
        value="0.00138867181880573" />
      <inertia
        ixx="8.31791309546734E-08"
        ixy="-7.83803287628791E-13"
        ixz="-8.15452233848557E-10"
        iyy="7.77088477685041E-08"
        iyz="-1.73077042516637E-12"
        izz="2.23707352283295E-08" />
    </inertial>
    <visual>
      <origin
        xyz="-0.404364999480808 0.00671475420528798 0.0105047646299231"
        rpy="3.14159264995864 1.5707962257303 3.14159264995864" />
      <geometry>
        <mesh
          filename="package://hand_v3_model/meshes/ring_link2.3dxml" />
      </geometry>
      <material
        name="">
        <color
          rgba="0.752941176470588 0.752941176470588 0.752941176470588 1" />
      </material>
    </visual>
    <collision>
      <origin
        xyz="-0.404364999480808 0.00671475420528798 0.0105047646299231"
        rpy="3.14159264995864 1.5707962257303 3.14159264995864" />
      <geometry>
        <mesh
          filename="package://hand_v3_model/meshes/ring_link2.3dxml" />
      </geometry>
    </collision>
  </link>
  <joint
    name="ring_joint2"
    type="revolute">
    <origin
      xyz="0.034 0 0"
      rpy="0 0 0" />
    <parent
      link="ring_link1" />
    <child
      link="ring_link2" />
    <axis
      xyz="0 -1 0" />
    <limit
      lower="0"
      upper="1.5708"
      effort="0"
      velocity="10" />
  </joint>
  <link
    name="ring_link3">
    <inertial>
      <origin
        xyz="-0.42592465717889 0.00671473460798005 0.00236116864609563"
        rpy="0 0 0" />
      <mass
        value="0.00106407623116358" />
      <inertia
        ixx="5.23142399203294E-08"
        ixy="-1.51110018988025E-13"
        ixz="-3.63902192429204E-09"
        iyy="4.8789779132009E-08"
        iyz="-2.53656412409941E-13"
        izz="1.45110052052983E-08" />
    </inertial>
    <visual>
      <origin
        xyz="-0.427364999480808 0.00671475420528813 0.0105047646299231"
        rpy="3.14159264969729 1.5707962257303 3.14159264969729" />
      <geometry>
        <mesh
          filename="package://hand_v3_model/meshes/ring_link3.3dxml" />
      </geometry>
      <material
        name="">
        <color
          rgba="0.752941176470588 0.752941176470588 0.752941176470588 1" />
      </material>
    </visual>
    <collision>
      <origin
        xyz="-0.427364999480808 0.00671475420528813 0.0105047646299231"
        rpy="3.14159264969729 1.5707962257303 3.14159264969729" />
      <geometry>
        <mesh
          filename="package://hand_v3_model/meshes/ring_link3.3dxml" />
      </geometry>
    </collision>
  </link>
  <joint
    name="ring_joint3"
    type="revolute">
    <origin
      xyz="0.0230000000000001 0 0"
      rpy="0 0 0" />
    <parent
      link="ring_link2" />
    <child
      link="ring_link3" />
    <axis
      xyz="0 -1 0" />
    <limit
      lower="0"
      upper="1.5708"
      effort="0"
      velocity="10" />
  </joint>
  <link
    name="little_link0">
    <inertial>
      <origin
        xyz="-0.354246569885181 0.0251833629073577 0.00456488752201531"
        rpy="0 0 0" />
      <mass
        value="0.000862121012813642" />
      <inertia
        ixx="2.74833063697148E-08"
        ixy="-4.6001529297172E-11"
        ixz="1.64625439575554E-09"
        iyy="2.48141488184599E-08"
        iyz="2.92884480539031E-10"
        izz="1.83268341935774E-08" />
    </inertial>
    <visual>
      <origin
        xyz="-0.354299998213794 0.0248147534713826 0.00900476462980943"
        rpy="3.14159265006496 1.5707962257303 3.14159265006495" />
      <geometry>
        <mesh
          filename="package://hand_v3_model/meshes/little_link0.3dxml" />
      </geometry>
      <material
        name="">
        <color
          rgba="0.792156862745098 0.819607843137255 0.933333333333333 1" />
      </material>
    </visual>
    <collision>
      <origin
        xyz="-0.354299998213794 0.0248147534713826 0.00900476462980943"
        rpy="3.14159265006496 1.5707962257303 3.14159265006495" />
      <geometry>
        <mesh
          filename="package://hand_v3_model/meshes/little_link0.3dxml" />
      </geometry>
    </collision>
  </link>
  <joint
    name="little_joint0"
    type="revolute">
    <origin
      xyz="0.00900472894422229 -0.0248147534713593 0.0965999991207631"
      rpy="-3.14159260409306 -1.57079622683487 3.14159260409306" />
    <parent
      link="hand_link" />
    <child
      link="little_link0" />
    <axis
      xyz="0 0 -0.999999999999985" />
    <limit
      lower="-1.2217"
      upper="0"
      effort="0"
      velocity="6.545" />
  </joint>
  <link
    name="little_link1">
    <inertial>
      <origin
        xyz="-0.364507626849103 0.0247146509018844 -1.40645439668172E-05"
        rpy="0 0 0" />
      <mass
        value="0.00138867181880572" />
      <inertia
        ixx="8.31791309546738E-08"
        ixy="-7.83803287616177E-13"
        ixz="-8.15452233848282E-10"
        iyy="7.77088477685046E-08"
        iyz="-1.73077042514485E-12"
        izz="2.23707352283295E-08" />
    </inertial>
    <visual>
      <origin
        xyz="-0.365364999480807 0.0247147542052884 0.0105047646298095"
        rpy="3.14159265034958 1.5707962257303 3.14159265034958" />
      <geometry>
        <mesh
          filename="package://hand_v3_model/meshes/little_link1.3dxml" />
      </geometry>
      <material
        name="">
        <color
          rgba="0.752941176470588 0.752941176470588 0.752941176470588 1" />
      </material>
    </visual>
    <collision>
      <origin
        xyz="-0.365364999480807 0.0247147542052884 0.0105047646298095"
        rpy="3.14159265034958 1.5707962257303 3.14159265034958" />
      <geometry>
        <mesh
          filename="package://hand_v3_model/meshes/little_link1.3dxml" />
      </geometry>
    </collision>
  </link>
  <joint
    name="little_joint1"
    type="revolute">
    <origin
      xyz="0.0110650012670137 9.99992660936123E-05 -0.0015"
      rpy="0 0 0" />
    <parent
      link="little_link0" />
    <child
      link="little_link1" />
    <axis
      xyz="0 1 0" />
    <limit
      lower="0"
      upper="1.5708"
      effort="0"
      velocity="10" />
  </joint>
  <link
    name="little_link2">
    <inertial>
      <origin
        xyz="-0.387507626849111 0.0247146509018449 -1.4064543966439E-05"
        rpy="0 0 0" />
      <mass
        value="0.0013886718188057" />
      <inertia
        ixx="8.31791309546721E-08"
        ixy="-7.83803287853618E-13"
        ixz="-8.15452233849782E-10"
        iyy="7.77088477685027E-08"
        iyz="-1.73077042580625E-12"
        izz="2.2370735228329E-08" />
    </inertial>
    <visual>
      <origin
        xyz="-0.388364999480807 0.0247147542052882 0.0105047646298094"
        rpy="3.14159265019532 1.57079622355662 3.14159265019532" />
      <geometry>
        <mesh
          filename="package://hand_v3_model/meshes/little_link2.3dxml" />
      </geometry>
      <material
        name="">
        <color
          rgba="0.752941176470588 0.752941176470588 0.752941176470588 1" />
      </material>
    </visual>
    <collision>
      <origin
        xyz="-0.388364999480807 0.0247147542052882 0.0105047646298094"
        rpy="3.14159265019532 1.57079622355662 3.14159265019532" />
      <geometry>
        <mesh
          filename="package://hand_v3_model/meshes/little_link2.3dxml" />
      </geometry>
    </collision>
  </link>
  <joint
    name="little_joint2"
    type="revolute">
    <origin
      xyz="0.023 0 0"
      rpy="0 0 0" />
    <parent
      link="little_link1" />
    <child
      link="little_link2" />
    <axis
      xyz="0 1 0" />
    <limit
      lower="0"
      upper="1.5708"
      effort="0"
      velocity="10" />
  </joint>
  <link
    name="little_link3">
    <inertial>
      <origin
        xyz="-0.409924657179012 0.0247147346079994 0.00236116864598134"
        rpy="0 0 0" />
      <mass
        value="0.00106407623116358" />
      <inertia
        ixx="5.23142399203297E-08"
        ixy="-1.51110019092363E-13"
        ixz="-3.63902192429213E-09"
        iyy="4.87897791320094E-08"
        iyz="-2.53656411614198E-13"
        izz="1.45110052052982E-08" />
    </inertial>
    <visual>
      <origin
        xyz="-0.411364999480807 0.0247147542052885 0.0105047646298093"
        rpy="3.14159264770445 1.5707962257303 3.14159264770445" />
      <geometry>
        <mesh
          filename="package://hand_v3_model/meshes/little_link3.3dxml" />
      </geometry>
      <material
        name="">
        <color
          rgba="0.752941176470588 0.752941176470588 0.752941176470588 1" />
      </material>
    </visual>
    <collision>
      <origin
        xyz="-0.411364999480807 0.0247147542052885 0.0105047646298093"
        rpy="3.14159264770445 1.5707962257303 3.14159264770445" />
      <geometry>
        <mesh
          filename="package://hand_v3_model/meshes/little_link3.3dxml" />
      </geometry>
    </collision>
  </link>
  <joint
    name="little_joint3"
    type="revolute">
    <origin
      xyz="0.023 0 0"
      rpy="0 0 0" />
    <parent
      link="little_link2" />
    <child
      link="little_link3" />
    <axis
      xyz="0 1 0" />
    <limit
      lower="0"
      upper="1.5708"
      effort="0"
      velocity="10" />
  </joint>
</robot>